Workbook

Sheet Dashboard
A1: E-commerce Performance Dashboard
A2: Order data 2020-10-29 → 2025-12-01 · Realised sales = Completed + Returned orders · Amounts in currency units as recorded
A4: Net revenue | E4: Refunds (approved) | I4: Orders | M4: Repeat rate (90d) | Q4: Orders with payment issue | U4: Est. loss on below-cost sales
A5: =SUMIFS(Curated_Items!$S$5:$S$771,Curated_Items!$T$5:$T$771,1) -> 19164568 | E5: =SUMIFS(Curated_Items!$Q$5:$Q$771,Curated_Items!$T$5:$T$771,1) -> 815331.14 | I5: =SUMPRODUCT((Curated_Items!$T$5:$T$771=1)/COUNTIFS(Curated_Items!$B$5:$B$771,Curated_Items!$B$5:$B$771)) -> 223 | M5: =KPI7_Repeat_Rate!B6 -> 0.091836735 | Q5: =COUNTIF(KPI8_Payment_Recon!H5:H332,"<>OK") -> 218 | U5: =KPI9_Margin_Risk!C7 -> 1795100.8
A7: Net revenue by month (KPI 1) | M7: Net revenue by category (KPI 1)
A25: Net revenue by channel, 2024–25 (KPI 4) | M25: Average order value by segment (KPI 3)
A43: Top 10 customers by net LTV (KPI 2) | M43: Top 10 supplier composite score (KPI 6)
A61: Product return rate — highest 10 (KPI 5) | M61: Payment reconciliation flags (KPI 8)
A80: Key assumptions: see Assumptions_README sheet. Dashboard tiles and KPI 1 are live formulas on Curated_Items; other KPI tables are pipeline outputs (pipeline.py) with formulas for totals, scores and MoM.

Sheet KPI1_Net_Revenue
A1: KPI 1 · Net revenue by product category, per month
A2: Net revenue = line revenue after discount − approved refunds, attributed to ORDER month. Only Completed + Returned orders (Cancelled/Pending excluded). Live SUMIFS on Curated_Items.
A4: Month | B4: Electronics | C4: Fashion | D4: Grocery | E4: Home & Kitchen | F4: Sports | G4: Unknown | H4: Total
A5: 2020-10 | B5: =SUMIFS(Curated_Items!$S$5:$S$771,Curated_Items!$D$5:$D$771,$A5,Curated_Items!$H$5:$H$771,B$4,Curated_Items!$T$5:$T$771,1) -> 0 | C5: =SUMIFS(Curated_Items!$S$5:$S$771,Curated_Items!$D$5:$D$771,$A5,Curated_Items!$H$5:$H$771,C$4,Curated_Items!$T$5:$T$771,1) -> 0 | D5: =SUMIFS(Curated_Items!$S$5:$S$771,Curated_Items!$D$5:$D$771,$A5,Curated_Items!$H$5:$H$771,D$4,Curated_Items!$T$5:$T$771,1) -> 45144.5 | E5: =SUMIFS(Curated_Items!$S$5:$S$771,Curated_Items!$D$5:$D$771,$A5,Curated_Items!$H$5:$H$771,E$4,Curated_Items!$T$5:$T$771,1) -> 0 | F5: =SUMIFS(Curated_Items!$S$5:$S$771,Curated_Items!$D$5:$D$771,$A5,Curated_Items!$H$5:$H$771,F$4,Curated_Items!$T$5:$T$771,1) -> 0 | G5: =SUMIFS(Curated_Items!$S$5:$S$771,Curated_Items!$D$5:$D$771,$A5,Curated_Items!$H$5:$H$771,G$4,Curated_Items!$T$5:$T$771,1) -> 0 | H5: =SUM(B5:G5) -> 45144.5
A6: 2020-12 | B6: =SUMIFS(Curated_Items!$S$5:$S$771,Curated_Items!$D$5:$D$771,$A6,Curated_Items!$H$5:$H$771,B$4,Curated_Items!$T$5:$T$771,1) -> 0 | C6: =SUMIFS(Curated_Items!$S$5:$S$771,Curated_Items!$D$5:$D$771,$A6,Curated_Items!$H$5:$H$771,C$4,Curated_Items!$T$5:$T$771,1) -> 0 | D6: =SUMIFS(Curated_Items!$S$5:$S$771,Curated_Items!$D$5:$D$771,$A6,Curated_Items!$H$5:$H$771,D$4,Curated_Items!$T$5:$T$771,1) -> 0 | E6: =SUMIFS(Curated_Items!$S$5:$S$771,Curated_Items!$D$5:$D$771,$A6,Curated_Items!$H$5:$H$771,E$4,Curated_Items!$T$5:$T$771,1) -> 21122.18 | F6: =SUMIFS(Curated_Items!$S$5:$S$771,Curated_Items!$D$5:$D$771,$A6,Curated_Items!$H$5:$H$771,F$4,Curated_Items!$T$5:$T$771,1) -> 0 | G6: =SUMIFS(Curated_Items!$S$5:$S$771,Curated_Items!$D$5:$D$771,$A6,Curated_Items!$H$5:$H$771,G$4,Curated_Items!$T$5:$T$771,1) -> 0 | H6: =SUM(B6:G6) -> 21122.18
A7: 2021-05 | B7: =SUMIFS(Curated_Items!$S$5:$S$771,Curated_Items!$D$5:$D$771,$A7,Curated_Items!$H$5:$H$771,B$4,Curated_Items!$T$5:$T$771,1) -> 16084.14 | C7: =SUMIFS(Curated_Items!$S$5:$S$771,Curated_Items!$D$5:$D$771,$A7,Curated_Items!$H$5:$H$771,C$4,Curated_Items!$T$5:$T$771,1) -> 0 | D7: =SUMIFS(Curated_Items!$S$5:$S$771,Curated_Items!$D$5:$D$771,$A7,Curated_Items!$H$5:$H$771,D$4,Curated_Items!$T$5:$T$771,1) -> 88376.89 | E7: =SUMIFS(Curated_Items!$S$5:$S$771,Curated_Items!$D$5:$D$771,$A7,Curated_Items!$H$5:$H$771,E$4,Curated_Items!$T$5:$T$771,1) -> 0 | F7: =SUMIFS(Curated_Items!$S$5:$S$771,Curated_Items!$D$5:$D$771,$A7,Curated_Items!$H$5:$H$771,F$4,Curated_Items!$T$5:$T$771,1) -> 0 | G7: =SUMIFS(Curated_Items!$S$5:$S$771,Curated_Items!$D$5:$D$771,$A7,Curated_Items!$H$5:$H$771,G$4,Curated_Items!$T$5:$T$771,1) -> 0 | H7: =SUM(B7:G7) -> 104461.03
A8: 2021-09 | B8: =SUMIFS(Curated_Items!$S$5:$S$771,Curated_Items!$D$5:$D$771,$A8,Curated_Items!$H$5:$H$771,B$4,Curated_Items!$T$5:$T$771,1) -> 0 | C8: =SUMIFS(Curated_Items!$S$5:$S$771,Curated_Items!$D$5:$D$771,$A8,Curated_Items!$H$5:$H$771,C$4,Curated_Items!$T$5:$T$771,1) -> 0 | D8: =SUMIFS(Curated_Items!$S$5:$S$771,Curated_Items!$D$5:$D$771,$A8,Curated_Items!$H$5:$H$771,D$4,Curated_Items!$T$5:$T$771,1) -> 13037.07 | E8: =SUMIFS(Curated_Items!$S$5:$S$771,Curated_Items!$D$5:$D$771,$A8,Curated_Items!$H$5:$H$771,E$4,Curated_Items!$T$5:$T$771,1) -> 56241.65 | F8: =SUMIFS(Curated_Items!$S$5:$S$771,Curated_Items!$D$5:$D$771,$A8,Curated_Items!$H$5:$H$771,F$4,Curated_Items!$T$5:$T$771,1) -> 0 | G8: =SUMIFS(Curated_Items!$S$5:$S$771,Curated_Items!$D$5:$D$771,$A8,Curated_Items!$H$5:$H$771,G$4,Curated_Items!$T$5:$T$771,1) -> 0 | H8: =SUM(B8:G8) -> 69278.72
A9: 2022-10 | B9: =SUMIFS(Curated_Items!$S$5:$S$771,Curated_Items!$D$5:$D$771,$A9,Curated_Items!$H$5:$H$771,B$4,Curated_Items!$T$5:$T$771,1) -> 0 | C9: =SUMIFS(Curated_Items!$S$5:$S$771,Curated_Items!$D$5:$D$771,$A9,Curated_Items!$H$5:$H$771,C$4,Curated_Items!$T$5:$T$771,1) -> 9607.25 | D9: =SUMIFS(Curated_Items!$S$5:$S$771,Curated_Items!$D$5:$D$771,$A9,Curated_Items!$H$5:$H$771,D$4,Curated_Items!$T$5:$T$771,1) -> 17582.77 | E9: =SUMIFS(Curated_Items!$S$5:$S$771,Curated_Items!$D$5:$D$771,$A9,Curated_Items!$H$5:$H$771,E$4,Curated_Items!$T$5:$T$771,1) -> 0 | F9: =SUMIFS(Curated_Items!$S$5:$S$771,Curated_Items!$D$5:$D$771,$A9,Curated_Items!$H$5:$H$771,F$4,Curated_Items!$T$5:$T$771,1) -> 81924.16 | G9: =SUMIFS(Curated_Items!$S$5:$S$771,Curated_Items!$D$5:$D$771,$A9,Curated_Items!$H$5:$H$771,G$4,Curated_Items!$T$5:$T$771,1) -> 0 | H9: =SUM(B9:G9) -> 109114.18
A10: 2024-01 | B10: =SUMIFS(Curated_Items!$S$5:$S$771,Curated_Items!$D$5:$D$771,$A10,Curated_Items!$H$5:$H$771,B$4,Curated_Items!$T$5:$T$771,1) -> 154568.75 | C10: =SUMIFS(Curated_Items!$S$5:$S$771,Curated_Items!$D$5:$D$771,$A10,Curated_Items!$H$5:$H$771,C$4,Curated_Items!$T$5:$T$771,1) -> 70908.67 | D10: =SUMIFS(Curated_Items!$S$5:$S$771,Curated_Items!$D$5:$D$771,$A10,Curated_Items!$H$5:$H$771,D$4,Curated_Items!$T$5:$T$771,1) -> 212099.87 | E10: =SUMIFS(Curated_Items!$S$5:$S$771,Curated_Items!$D$5:$D$771,$A10,Curated_Items!$H$5:$H$771,E$4,Curated_Items!$T$5:$T$771,1) -> 235968.07 | F10: =SUMIFS(Curated_Items!$S$5:$S$771,Curated_Items!$D$5:$D$771,$A10,Curated_Items!$H$5:$H$771,F$4,Curated_Items!$T$5:$T$771,1) -> 33174.22 | G10: =SUMIFS(Curated_Items!$S$5:$S$771,Curated_Items!$D$5:$D$771,$A10,Curated_Items!$H$5:$H$771,G$4,Curated_Items!$T$5:$T$771,1) -> 0 | H10: =SUM(B10:G10) -> 706719.58
A11: 2024-02 | B11: =SUMIFS(Curated_Items!$S$5:$S$771,Curated_Items!$D$5:$D$771,$A11,Curated_Items!$H$5:$H$771,B$4,Curated_Items!$T$5:$T$771,1) -> 117501.07 | C11: =SUMIFS(Curated_Items!$S$5:$S$771,Curated_Items!$D$5:$D$771,$A11,Curated_Items!$H$5:$H$771,C$4,Curated_Items!$T$5:$T$771,1) -> 336016.22 | D11: =SUMIFS(Curated_Items!$S$5:$S$771,Curated_Items!$D$5:$D$771,$A11,Curated_Items!$H$5:$H$771,D$4,Curated_Items!$T$5:$T$771,1) -> 105096.8 | E11: =SUMIFS(Curated_Items!$S$5:$S$771,Curated_Items!$D$5:$D$771,$A11,Curated_Items!$H$5:$H$771,E$4,Curated_Items!$T$5:$T$771,1) -> 141153.75 | F11: =SUMIFS(Curated_Items!$S$5:$S$771,Curated_Items!$D$5:$D$771,$A11,Curated_Items!$H$5:$H$771,F$4,Curated_Items!$T$5:$T$771,1) -> 60151.91 | G11: =SUMIFS(Curated_Items!$S$5:$S$771,Curated_Items!$D$5:$D$771,$A11,Curated_Items!$H$5:$H$771,G$4,Curated_Items!$T$5:$T$771,1) -> 0 | H11: =SUM(B11:G11) -> 759919.75
A12: 2024-03 | B12: =SUMIFS(Curated_Items!$S$5:$S$771,Curated_Items!$D$5:$D$771,$A12,Curated_Items!$H$5:$H$771,B$4,Curated_Items!$T$5:$T$771,1) -> 106461.26 | C12: =SUMIFS(Curated_Items!$S$5:$S$771,Curated_Items!$D$5:$D$771,$A12,Curated_Items!$H$5:$H$771,C$4,Curated_Items!$T$5:$T$771,1) -> 243040.65 | D12: =SUMIFS(Curated_Items!$S$5:$S$771,Curated_Items!$D$5:$D$771,$A12,Curated_Items!$H$5:$H$771,D$4,Curated_Items!$T$5:$T$771,1) -> 285106.27 | E12: =SUMIFS(Curated_Items!$S$5:$S$771,Curated_Items!$D$5:$D$771,$A12,Curated_Items!$H$5:$H$771,E$4,Curated_Items!$T$5:$T$771,1) -> 183928.33 | F12: =SUMIFS(Curated_Items!$S$5:$S$771,Curated_Items!$D$5:$D$771,$A12,Curated_Items!$H$5:$H$771,F$4,Curated_Items!$T$5:$T$771,1) -> 77531.86 | G12: =SUMIFS(Curated_Items!$S$5:$S$771,Curated_Items!$D$5:$D$771,$A12,Curated_Items!$H$5:$H$771,G$4,Curated_Items!$T$5:$T$771,1) -> 0 | H12: =SUM(B12:G12) -> 896068.37
A13: 2024-04 | B13: =SUMIFS(Curated_Items!$S$5:$S$771,Curated_Items!$D$5:$D$771,$A13,Curated_Items!$H$5:$H$771,B$4,Curated_Items!$T$5:$T$771,1) -> 95577.03 | C13: =SUMIFS(Curated_Items!$S$5:$S$771,Curated_Items!$D$5:$D$771,$A13,Curated_Items!$H$5:$H$771,C$4,Curated_Items!$T$5:$T$771,1) -> 106497.74 | D13: =SUMIFS(Curated_Items!$S$5:$S$771,Curated_Items!$D$5:$D$771,$A13,Curated_Items!$H$5:$H$771,D$4,Curated_Items!$T$5:$T$771,1) -> 34155.34 | E13: =SUMIFS(Curated_Items!$S$5:$S$771,Curated_Items!$D$5:$D$771,$A13,Curated_Items!$H$5:$H$771,E$4,Curated_Items!$T$5:$T$771,1) -> 118109.27 | F13: =SUMIFS(Curated_Items!$S$5:$S$771,Curated_Items!$D$5:$D$771,$A13,Curated_Items!$H$5:$H$771,F$4,Curated_Items!$T$5:$T$771,1) -> 175708.52 | G13: =SUMIFS(Curated_Items!$S$5:$S$771,Curated_Items!$D$5:$D$771,$A13,Curated_Items!$H$5:$H$771,G$4,Curated_Items!$T$5:$T$771,1) -> 0 | H13: =SUM(B13:G13) -> 530047.9
A14: 2024-05 | B14: =SUMIFS(Curated_Items!$S$5:$S$771,Curated_Items!$D$5:$D$771,$A14,Curated_Items!$H$5:$H$771,B$4,Curated_Items!$T$5:$T$771,1) -> 87407.72 | C14: =SUMIFS(Curated_Items!$S$5:$S$771,Curated_Items!$D$5:$D$771,$A14,Curated_Items!$H$5:$H$771,C$4,Curated_Items!$T$5:$T$771,1) -> 207823.27 | D14: =SUMIFS(Curated_Items!$S$5:$S$771,Curated_Items!$D$5:$D$771,$A14,Curated_Items!$H$5:$H$771,D$4,Curated_Items!$T$5:$T$771,1) -> 52748.3 | E14: =SUMIFS(Curated_Items!$S$5:$S$771,Curated_Items!$D$5:$D$771,$A14,Curated_Items!$H$5:$H$771,E$4,Curated_Items!$T$5:$T$771,1) -> 158595.93 | F14: =SUMIFS(Curated_Items!$S$5:$S$771,Curated_Items!$D$5:$D$771,$A14,Curated_Items!$H$5:$H$771,F$4,Curated_Items!$T$5:$T$771,1) -> 46075.44 | G14: =SUMIFS(Curated_Items!$S$5:$S$771,Curated_Items!$D$5:$D$771,$A14,Curated_Items!$H$5:$H$771,G$4,Curated_Items!$T$5:$T$771,1) -> 0 | H14: =SUM(B14:G14) -> 552650.66
A15: 2024-06 | B15: =SUMIFS(Curated_Items!$S$5:$S$771,Curated_Items!$D$5:$D$771,$A15,Curated_Items!$H$5:$H$771,B$4,Curated_Items!$T$5:$T$771,1) -> 66132.8 | C15: =SUMIFS(Curated_Items!$S$5:$S$771,Curated_Items!$D$5:$D$771,$A15,Curated_Items!$H$5:$H$771,C$4,Curated_Items!$T$5:$T$771,1) -> 427275.13 | D15: =SUMIFS(Curated_Items!$S$5:$S$771,Curated_Items!$D$5:$D$771,$A15,Curated_Items!$H$5:$H$771,D$4,Curated_Items!$T$5:$T$771,1) -> 437611.63 | E15: =SUMIFS(Curated_Items!$S$5:$S$771,Curated_Items!$D$5:$D$771,$A15,Curated_Items!$H$5:$H$771,E$4,Curated_Items!$T$5:$T$771,1) -> 272902.43 | F15: =SUMIFS(Curated_Items!$S$5:$S$771,Curated_Items!$D$5:$D$771,$A15,Curated_Items!$H$5:$H$771,F$4,Curated_Items!$T$5:$T$771,1) -> 185970.02 | G15: =SUMIFS(Curated_Items!$S$5:$S$771,Curated_Items!$D$5:$D$771,$A15,Curated_Items!$H$5:$H$771,G$4,Curated_Items!$T$5:$T$771,1) -> 0 | H15: =SUM(B15:G15) -> 1389892
A16: 2024-07 | B16: =SUMIFS(Curated_Items!$S$5:$S$771,Curated_Items!$D$5:$D$771,$A16,Curated_Items!$H$5:$H$771,B$4,Curated_Items!$T$5:$T$771,1) -> 41429.58 | C16: =SUMIFS(Curated_Items!$S$5:$S$771,Curated_Items!$D$5:$D$771,$A16,Curated_Items!$H$5:$H$771,C$4,Curated_Items!$T$5:$T$771,1) -> 116679.51 | D16: =SUMIFS(Curated_Items!$S$5:$S$771,Curated_Items!$D$5:$D$771,$A16,Curated_Items!$H$5:$H$771,D$4,Curated_Items!$T$5:$T$771,1) -> 105216.93 | E16: =SUMIFS(Curated_Items!$S$5:$S$771,Curated_Items!$D$5:$D$771,$A16,Curated_Items!$H$5:$H$771,E$4,Curated_Items!$T$5:$T$771,1) -> 247681.29 | F16: =SUMIFS(Curated_Items!$S$5:$S$771,Curated_Items!$D$5:$D$771,$A16,Curated_Items!$H$5:$H$771,F$4,Curated_Items!$T$5:$T$771,1) -> 66447.79 | G16: =SUMIFS(Curated_Items!$S$5:$S$771,Curated_Items!$D$5:$D$771,$A16,Curated_Items!$H$5:$H$771,G$4,Curated_Items!$T$5:$T$771,1) -> 18998.55 | H16: =SUM(B16:G16) -> 596453.65
... A32: 2025-12 | B32: =SUMIFS(Curated_Items!$S$5:$S$771,Curated_Items!$D$5:$D$771,$A32,Curated_Items!$H$5:$H$771,B$4,Curated_Items!$T$5:$T$771,1) -> 15383.27 | C32: =SUMIFS(Curated_Items!$S$5:$S$771,Curated_Items!$D$5:$D$771,$A32,Curated_Items!$H$5:$H$771,C$4,Curated_Items!$T$5:$T$771,1) -> 17597.06 | D32: =SUMIFS(Curated_Items!$S$5:$S$771,Curated_Items!$D$5:$D$771,$A32,Curated_Items!$H$5:$H$771,D$4,Curated_Items!$T$5:$T$771,1) -> 0 | E32: =SUMIFS(Curated_Items!$S$5:$S$771,Curated_Items!$D$5:$D$771,$A32,Curated_Items!$H$5:$H$771,E$4,Curated_Items!$T$5:$T$771,1) -> 3308 | F32: =SUMIFS(Curated_Items!$S$5:$S$771,Curated_Items!$D$5:$D$771,$A32,Curated_Items!$H$5:$H$771,F$4,Curated_Items!$T$5:$T$771,1) -> 101394.45 | G32: =SUMIFS(Curated_Items!$S$5:$S$771,Curated_Items!$D$5:$D$771,$A32,Curated_Items!$H$5:$H$771,G$4,Curated_Items!$T$5:$T$771,1) -> 0 | H32: =SUM(B32:G32) -> 137682.78
A33: Total | B33: =SUM(B5:B32) -> 2569374.4 | C33: =SUM(C5:C32) -> 4024835.6 | D33: =SUM(D5:D32) -> 4920588.5 | E33: =SUM(E5:E32) -> 4834145.2 | F33: =SUM(F5:F32) -> 2677280.6 | G33: =SUM(G5:G32) -> 138343.58 | H33: =SUM(H5:H32) -> 19164568
A34: Check vs pipeline | H34: 19164568
A35: Difference | H35: =H33-H34 -> 0

Sheet KPI2_Top_Customers
A1: KPI 2 · Top 10 customers by net lifetime value
A2: Completed orders only, net of approved refunds. Orders with unknown customer (key −1) cannot be attributed and are excluded from the ranking; their value is shown as a memo line.
A4: rank | B4: customer_id | C4: full_name | D4: customer_segment | E4: city | F4: orders | G4: gross_spend | H4: refunds | I4: net_ltv
A5: 1 | B5: C0118 | C5: Utkarsh Bhat | D5: Gold | E5: Hyderabad | F5: 3 | G5: 532447.01 | H5: 0 | I5: 532447.01
A6: 2 | B6: C0107 | C6: Eesha Sethi | D6: Silver | E6: Kolkata | F6: 2 | G6: 463604.51 | H6: 0 | I6: 463604.51
A7: 3 | B7: C0061 | C7: Yadavi Bhakta | D7: Platinum | E7: Chennai | F7: 2 | G7: 341730.61 | H7: 0 | I7: 341730.61
A8: 4 | B8: C0148 | C8: Ucchal Thaker | D8: Bronze | E8: Jaipur | F8: 3 | G8: 329199.63 | H8: 0 | I8: 329199.63
A9: 5 | B9: C0142 | C9: Zansi Prasad | D9: Platinum | E9: Ahmedabad | F9: 4 | G9: 328510.35 | H9: 0 | I9: 328510.35
A10: 6 | B10: C0001 | C10: Isaac Bakshi | D10: Bronze | E10: Bangalore | F10: 4 | G10: 377880.04 | H10: 75816.05 | I10: 302063.99
A11: 7 | B11: C0085 | C11: Chakrika Koshy | D11: Silver | E11: Chennai | F11: 3 | G11: 291047.36 | H11: 0 | I11: 291047.36
A12: 8 | B12: C0033 | C12: Hamsini Rao | D12: Gold | E12: Lucknow | F12: 2 | G12: 268013.97 | H12: 0 | I12: 268013.97
A13: 9 | B13: C0129 | C13: Siddharth Bains | D13: Platinum | E13: New Delhi | F13: 3 | G13: 284905.07 | H13: 19128.89 | I13: 265776.18
A14: 10 | B14: C0037 | C14: Gautam Rana | D14: Gold | E14: Jaipur | F14: 2 | G14: 259380.42 | H14: 0 | I14: 259380.42
A16: Memo: completed-order net revenue with unknown customer (excluded) | I16: 562442.51

Sheet KPI3_Segments
A1: KPI 3 · Standardized customer segment profile
A2: customer_count = customers in the dimension per segment (placeholder UNKNOWN row excluded). AOV = completed-order net revenue ÷ distinct completed orders for customers in that segment.
A4: segment | B4: customer_count | C4: ordering_customers | D4: orders | E4: revenue | F4: avg_order_value
A5: Bronze | B5: 36 | C5: 22 | D5: 36 | E5: 2747177.5 | F5: 76310.488
A6: Gold | B6: 38 | C6: 21 | D6: 33 | E6: 3234111.4 | F6: 98003.375
A7: Platinum | B7: 44 | C7: 30 | D7: 51 | E7: 4083493.4 | F7: 80068.499
A8: Silver | B8: 40 | C8: 25 | D8: 36 | E8: 3204268.1 | F8: 89007.448
A9: Total | B9: =SUM(B5:B8) -> 158 | C9: =SUM(C5:C8) -> 98 | D9: =SUM(D5:D8) -> 156 | E9: =SUM(E5:E8) -> 13269050 | F9: =E9/D9 -> 85058.016

Sheet KPI4_MoM_by_Channel
A1: KPI 4 · Month-over-month order volume & net revenue growth by channel
A2: Window: LAG() over month within channel (SQL equivalent in README). Dense window Jan-2024 → Dec-2025 (7 orders before 2024 are too sparse for MoM). MoM shows "n/a" when the prior month is zero. Net revenue as per KPI 1.
A4: Channel | B4: Month | C4: Orders | D4: Net revenue | E4: Orders MoM % | F4: Net revenue MoM % | I4: Month | J4: App | K4: Store | L4: Web
A5: App | B5: 2024-01 | C5: 6 | D5: 506719.81 | E5: n/a | F5: n/a | I5: 2024-01 | J5: =D5 -> 506719.81 | K5: =D29 -> 77292.09 | L5: =D53 -> 122707.68
A6: App | B6: 2024-02 | C6: 3 | D6: 328038.05 | E6: =IF(C5>0,C6/C5-1,"n/a") -> -0.5 | F6: =IF(D5>0,D6/D5-1,"n/a") -> -0.35262438 | I6: 2024-02 | J6: =D6 -> 328038.05 | K6: =D30 -> 176780.78 | L6: =D54 -> 255100.92
A7: App | B7: 2024-03 | C7: 5 | D7: 340581.28 | E7: =IF(C6>0,C7/C6-1,"n/a") -> 0.66666667 | F7: =IF(D6>0,D7/D6-1,"n/a") -> 0.038237119 | I7: 2024-03 | J7: =D7 -> 340581.28 | K7: =D31 -> 336137.86 | L7: =D55 -> 219349.23
A8: App | B8: 2024-04 | C8: 3 | D8: 272281.13 | E8: =IF(C7>0,C8/C7-1,"n/a") -> -0.4 | F8: =IF(D7>0,D8/D7-1,"n/a") -> -0.20053994 | I8: 2024-04 | J8: =D8 -> 272281.13 | K8: =D32 -> 22580.5 | L8: =D56 -> 235186.27
A9: App | B9: 2024-05 | C9: 2 | D9: 248097.95 | E9: =IF(C8>0,C9/C8-1,"n/a") -> -0.33333333 | F9: =IF(D8>0,D9/D8-1,"n/a") -> -0.088816952 | I9: 2024-05 | J9: =D9 -> 248097.95 | K9: =D33 -> 304552.71 | L9: =D57 -> 0
A10: App | B10: 2024-06 | C10: 9 | D10: 684406.22 | E10: =IF(C9>0,C10/C9-1,"n/a") -> 3.5 | F10: =IF(D9>0,D10/D9-1,"n/a") -> 1.758613 | I10: 2024-06 | J10: =D10 -> 684406.22 | K10: =D34 -> 563769.51 | L10: =D58 -> 141716.28
A11: App | B11: 2024-07 | C11: 5 | D11: 218621.63 | E11: =IF(C10>0,C11/C10-1,"n/a") -> -0.44444444 | F11: =IF(D10>0,D11/D10-1,"n/a") -> -0.68056744 | I11: 2024-07 | J11: =D11 -> 218621.63 | K11: =D35 -> 134606.36 | L11: =D59 -> 243225.66
A12: App | B12: 2024-08 | C12: 1 | D12: 60641.05 | E12: =IF(C11>0,C12/C11-1,"n/a") -> -0.8 | F12: =IF(D11>0,D12/D11-1,"n/a") -> -0.722621 | I12: 2024-08 | J12: =D12 -> 60641.05 | K12: =D36 -> 293046.3 | L12: =D60 -> 755648.42
A13: App | B13: 2024-09 | C13: 1 | D13: 190124.75 | E13: =IF(C12>0,C13/C12-1,"n/a") -> 0 | F13: =IF(D12>0,D13/D12-1,"n/a") -> 2.1352483 | I13: 2024-09 | J13: =D13 -> 190124.75 | K13: =D37 -> 633815.95 | L13: =D61 -> 360672.5
A14: App | B14: 2024-10 | C14: 3 | D14: 274270.91 | E14: =IF(C13>0,C14/C13-1,"n/a") -> 2 | F14: =IF(D13>0,D14/D13-1,"n/a") -> 0.44258394 | I14: 2024-10 | J14: =D14 -> 274270.91 | K14: =D38 -> 122920.6 | L14: =D62 -> 196517.69
A15: App | B15: 2024-11 | C15: 9 | D15: 953580.21 | E15: =IF(C14>0,C15/C14-1,"n/a") -> 2 | F15: =IF(D14>0,D15/D14-1,"n/a") -> 2.4767822 | I15: 2024-11 | J15: =D15 -> 953580.21 | K15: =D39 -> 499132.45 | L15: =D63 -> 0
A16: App | B16: 2024-12 | C16: 2 | D16: 254049.75 | E16: =IF(C15>0,C16/C15-1,"n/a") -> -0.77777778 | F16: =IF(D15>0,D16/D15-1,"n/a") -> -0.73358324 | I16: 2024-12 | J16: =D16 -> 254049.75 | K16: =D40 -> 322813.04 | L16: =D64 -> 305686.57
A17: App | B17: 2025-01 | C17: 4 | D17: 323432.52 | E17: =IF(C16>0,C17/C16-1,"n/a") -> 1 | F17: =IF(D16>0,D17/D16-1,"n/a") -> 0.27310702 | I17: 2025-01 | J17: =D17 -> 323432.52 | K17: =D41 -> 331101.22 | L17: =D65 -> 386589.1
... A28: App | B28: 2025-12 | C28: 0 | D28: 0 | E28: =IF(C27>0,C28/C27-1,"n/a") -> n/a | F28: =IF(D27>0,D28/D27-1,"n/a") -> n/a | I28: 2025-12 | J28: =D28 -> 0 | K28: =D52 -> 0 | L28: =D76 -> 137682.78
A29: Store | B29: 2024-01 | C29: 2 | D29: 77292.09 | E29: n/a | F29: n/a
A30: Store | B30: 2024-02 | C30: 2 | D30: 176780.78 | E30: =IF(C29>0,C30/C29-1,"n/a") -> 0 | F30: =IF(D29>0,D30/D29-1,"n/a") -> 1.2871782
A31: Store | B31: 2024-03 | C31: 4 | D31: 336137.86 | E31: =IF(C30>0,C31/C30-1,"n/a") -> 1 | F31: =IF(D30>0,D31/D30-1,"n/a") -> 0.90143895
A32: Store | B32: 2024-04 | C32: 1 | D32: 22580.5 | E32: =IF(C31>0,C32/C31-1,"n/a") -> -0.75 | F32: =IF(D31>0,D32/D31-1,"n/a") -> -0.93282369
A33: Store | B33: 2024-05 | C33: 4 | D33: 304552.71 | E33: =IF(C32>0,C33/C32-1,"n/a") -> 3 | F33: =IF(D32>0,D33/D32-1,"n/a") -> 12.487421
A34: Store | B34: 2024-06 | C34: 4 | D34: 563769.51 | E34: =IF(C33>0,C34/C33-1,"n/a") -> 0 | F34: =IF(D33>0,D34/D33-1,"n/a") -> 0.85113936
A35: Store | B35: 2024-07 | C35: 1 | D35: 134606.36 | E35: =IF(C34>0,C35/C34-1,"n/a") -> -0.75 | F35: =IF(D34>0,D35/D34-1,"n/a") -> -0.76123867
A36: Store | B36: 2024-08 | C36: 3 | D36: 293046.3 | E36: =IF(C35>0,C36/C35-1,"n/a") -> 2 | F36: =IF(D35>0,D36/D35-1,"n/a") -> 1.1770613
A37: Store | B37: 2024-09 | C37: 8 | D37: 633815.95 | E37: =IF(C36>0,C37/C36-1,"n/a") -> 1.6666667 | F37: =IF(D36>0,D37/D36-1,"n/a") -> 1.1628526
A38: Store | B38: 2024-10 | C38: 2 | D38: 122920.6 | E38: =IF(C37>0,C38/C37-1,"n/a") -> -0.75 | F38: =IF(D37>0,D38/D37-1,"n/a") -> -0.80606263
A39: Store | B39: 2024-11 | C39: 7 | D39: 499132.45 | E39: =IF(C38>0,C39/C38-1,"n/a") -> 2.5 | F39: =IF(D38>0,D39/D38-1,"n/a") -> 3.0606086
A40: Store | B40: 2024-12 | C40: 2 | D40: 322813.04 | E40: =IF(C39>0,C40/C39-1,"n/a") -> -0.71428571 | F40: =IF(D39>0,D40/D39-1,"n/a") -> -0.35325175
A41: Store | B41: 2025-01 | C41: 4 | D41: 331101.22 | E41: =IF(C40>0,C41/C40-1,"n/a") -> 1 | F41: =IF(D40>0,D41/D40-1,"n/a") -> 0.025674861
... A52: Store | B52: 2025-12 | C52: 0 | D52: 0 | E52: =IF(C51>0,C52/C51-1,"n/a") -> n/a | F52: =IF(D51>0,D52/D51-1,"n/a") -> n/a
A53: Web | B53: 2024-01 | C53: 1 | D53: 122707.68 | E53: n/a | F53: n/a
A54: Web | B54: 2024-02 | C54: 3 | D54: 255100.92 | E54: =IF(C53>0,C54/C53-1,"n/a") -> 2 | F54: =IF(D53>0,D54/D53-1,"n/a") -> 1.078932
A55: Web | B55: 2024-03 | C55: 2 | D55: 219349.23 | E55: =IF(C54>0,C55/C54-1,"n/a") -> -0.33333333 | F55: =IF(D54>0,D55/D54-1,"n/a") -> -0.14014724
A56: Web | B56: 2024-04 | C56: 4 | D56: 235186.27 | E56: =IF(C55>0,C56/C55-1,"n/a") -> 1 | F56: =IF(D55>0,D56/D55-1,"n/a") -> 0.072200117
A57: Web | B57: 2024-05 | C57: 0 | D57: 0 | E57: =IF(C56>0,C57/C56-1,"n/a") -> -1 | F57: =IF(D56>0,D57/D56-1,"n/a") -> -1
A58: Web | B58: 2024-06 | C58: 3 | D58: 141716.28 | E58: =IF(C57>0,C58/C57-1,"n/a") -> n/a | F58: =IF(D57>0,D58/D57-1,"n/a") -> n/a
A59: Web | B59: 2024-07 | C59: 5 | D59: 243225.66 | E59: =IF(C58>0,C59/C58-1,"n/a") -> 0.66666667 | F59: =IF(D58>0,D59/D58-1,"n/a") -> 0.71628595
A60: Web | B60: 2024-08 | C60: 5 | D60: 755648.42 | E60: =IF(C59>0,C60/C59-1,"n/a") -> 0 | F60: =IF(D59>0,D60/D59-1,"n/a") -> 2.1067792
A61: Web | B61: 2024-09 | C61: 2 | D61: 360672.5 | E61: =IF(C60>0,C61/C60-1,"n/a") -> -0.6 | F61: =IF(D60>0,D61/D60-1,"n/a") -> -0.522698
...

Sheet KPI5_Return_Rate
A1: KPI 5 · Product return rate — top 10 and bottom 10
A2: Return rate = returned qty ÷ ordered qty (Completed+Returned lines). Returned qty = full line quantity of APPROVED returns (the returns table has no partial quantities). Minimum volume threshold: 30 ordered units (19 of 69 products qualify). Ties broken by higher volume.
A4: Top 10 highest return rate
A5: product_id | B5: product_name | C5: category | D5: ordered_qty | E5: returned_qty | F5: return_rate
A6: P040 | B6: Footwear Item 40 | C6: Fashion | D6: 31 | E6: 5 | F6: 0.16129032
A7: P021 | B7: Fitness Item 21 | C7: Sports | D7: 35 | E7: 5 | F7: 0.14285714
A8: P042 | B8: Staples Item 42 | C8: Grocery | D8: 31 | E8: 3 | F8: 0.096774194
A9: P065 | B9: Footwear Item 65 | C9: Fashion | D9: 44 | E9: 4 | F9: 0.090909091
A10: P044 | B10: Beverages Item 44 | C10: Grocery | D10: 30 | E10: 1 | F10: 0.033333333
A11: P049 | B11: Beverages Item 49 | C11: Grocery | D11: 32 | E11: 1 | F11: 0.03125
A12: P007 | B12: Outdoor Item 7 | C12: Sports | D12: 36 | E12: 1 | F12: 0.027777778
A13: P054 | B13: Fitness Item 54 | C13: Sports | D13: 37 | E13: 1 | F13: 0.027027027
A14: P061 | B14: Furniture Item 61 | C14: Home & Kitchen | D14: 51 | E14: 0 | F14: 0
A15: P031 | B15: Accessories Item 31 | C15: Electronics | D15: 43 | E15: 0 | F15: 0
A17: Bottom 10 lowest return rate
A18: product_id | B18: product_name | C18: category | D18: ordered_qty | E18: returned_qty | F18: return_rate
A19: P061 | B19: Furniture Item 61 | C19: Home & Kitchen | D19: 51 | E19: 0 | F19: 0
A20: P031 | B20: Accessories Item 31 | C20: Electronics | D20: 43 | E20: 0 | F20: 0
A21: P012 | B21: Menswear Item 12 | C21: Fashion | D21: 40 | E21: 0 | F21: 0
A22: P068 | B22: Staples Item 68 | C22: Grocery | D22: 37 | E22: 0 | F22: 0
A23: P002 | B23: Furniture Item 2 | C23: Home & Kitchen | D23: 33 | E23: 0 | F23: 0
A24: P016 | B24: Footwear Item 16 | C24: Fashion | D24: 32 | E24: 0 | F24: 0
A25: P041 | B25: Cookware Item 41 | C25: Home & Kitchen | D25: 32 | E25: 0 | F25: 0
A26: P055 | B26: Staples Item 55 | C26: Grocery | D26: 32 | E26: 0 | F26: 0
A27: P004 | B27: Appliances Item 4 | C27: Home & Kitchen | D27: 30 | E27: 0 | F27: 0
A28: P037 | B28: Mobiles Item 37 | C28: Electronics | D28: 30 | E28: 0 | F28: 0

Sheet KPI6_Supplier_Scorecard
A1: KPI 6 · Supplier performance scorecard
A2: Composite (0–100) = 40% revenue (min-max) + 30% return performance (1 − min-max of avg product return rate) + 30% quality (rating_normalized ÷ 5). Ratings given on a 0–10 scale (raw > 5) were halved. Weights are inputs (blue) – scores recalculate.
A3: Weights: | C3: Revenue | D3: 0.4 | E3: Returns | F3: 0.3 | G3: Quality | H3: 0.3
A5: Rank | B5: Supplier | C5: ID | D5: Country | E5: Rating (raw) | F5: Rating (norm. /5) | G5: Products sold | H5: Net revenue | I5: Avg product return rate | J5: Revenue score | K5: Return score | L5: Composite score
A6: 1 | B6: Biswas, Karpe And Radhakrishnan | C6: S007 | D6: Unknown | E6: 4.2 | F6: 4.2 | G6: 6 | H6: 1861322.7 | I6: 0 | J6: =IF(MAX($H$6:$H$23)>MIN($H$6:$H$23),(H6-MIN($H$6:$H$23))/(MAX($H$6:$H$23)-MIN($H$6:$H$23)),0) -> 0.81831668 | K6: =IF(MAX($I$6:$I$23)>MIN($I$6:$I$23),1-(I6-MIN($I$6:$I$23))/(MAX($I$6:$I$23)-MIN($I$6:$I$23)),1) -> 1 | L6: =100*($D$3*J6+$F$3*K6+$H$3*F6/5) -> 87.932667
A7: 2 | B7: Lalla, Ganesh And Oommen | C7: S006 | D7: Germany | E7: 7.5 | F7: 3.75 | G7: 8 | H7: 2223174.1 | I7: 0.025718391 | J7: =IF(MAX($H$6:$H$23)>MIN($H$6:$H$23),(H7-MIN($H$6:$H$23))/(MAX($H$6:$H$23)-MIN($H$6:$H$23)),0) -> 1 | K7: =IF(MAX($I$6:$I$23)>MIN($I$6:$I$23),1-(I7-MIN($I$6:$I$23))/(MAX($I$6:$I$23)-MIN($I$6:$I$23)),1) -> 0.83926006 | L7: =100*($D$3*J7+$F$3*K7+$H$3*F7/5) -> 87.677802
A8: 3 | B8: Chaudhari, Sandal And Desai | C8: S015 | D8: India | E8: 4.1 | F8: 4.1 | G8: 4 | H8: 1821770.4 | I8: 0.022727273 | J8: =IF(MAX($H$6:$H$23)>MIN($H$6:$H$23),(H8-MIN($H$6:$H$23))/(MAX($H$6:$H$23)-MIN($H$6:$H$23)),0) -> 0.79845776 | K8: =IF(MAX($I$6:$I$23)>MIN($I$6:$I$23),1-(I8-MIN($I$6:$I$23))/(MAX($I$6:$I$23)-MIN($I$6:$I$23)),1) -> 0.85795455 | L8: =100*($D$3*J8+$F$3*K8+$H$3*F8/5) -> 82.276947
A9: 4 | B9: Amble, Prashad And Jha | C9: S004 | D9: Unknown | E9: 9.4 | F9: 4.7 | G9: 4 | H9: 1612831.4 | I9: 0.065247253 | J9: =IF(MAX($H$6:$H$23)>MIN($H$6:$H$23),(H9-MIN($H$6:$H$23))/(MAX($H$6:$H$23)-MIN($H$6:$H$23)),0) -> 0.69355078 | K9: =IF(MAX($I$6:$I$23)>MIN($I$6:$I$23),1-(I9-MIN($I$6:$I$23))/(MAX($I$6:$I$23)-MIN($I$6:$I$23)),1) -> 0.59220467 | L9: =100*($D$3*J9+$F$3*K9+$H$3*F9/5) -> 73.708171
A10: 5 | B10: Dhar-Gopal | C10: S005 | D10: Germany | E10: 4.5 | F10: 4.5 | G10: 2 | H10: 910835.68 | I10: 0 | J10: =IF(MAX($H$6:$H$23)>MIN($H$6:$H$23),(H10-MIN($H$6:$H$23))/(MAX($H$6:$H$23)-MIN($H$6:$H$23)),0) -> 0.3410832 | K10: =IF(MAX($I$6:$I$23)>MIN($I$6:$I$23),1-(I10-MIN($I$6:$I$23))/(MAX($I$6:$I$23)-MIN($I$6:$I$23)),1) -> 1 | L10: =100*($D$3*J10+$F$3*K10+$H$3*F10/5) -> 70.643328
A11: 6 | B11: Baral, Din And Bhalla | C11: S001 | D11: Unknown | E11: 4.3 | F11: 4.3 | G11: 3 | H11: 1336183.9 | I11: 0.070987654 | J11: =IF(MAX($H$6:$H$23)>MIN($H$6:$H$23),(H11-MIN($H$6:$H$23))/(MAX($H$6:$H$23)-MIN($H$6:$H$23)),0) -> 0.55464786 | K11: =IF(MAX($I$6:$I$23)>MIN($I$6:$I$23),1-(I11-MIN($I$6:$I$23))/(MAX($I$6:$I$23)-MIN($I$6:$I$23)),1) -> 0.55632716 | L11: =100*($D$3*J11+$F$3*K11+$H$3*F11/5) -> 64.675729
A12: 7 | B12: Amble, Virk And Dalal | C12: S018 | D12: Vietnam | E12: 5 | F12: 5 | G12: 4 | H12: 615765.99 | I12: 0.022727273 | J12: =IF(MAX($H$6:$H$23)>MIN($H$6:$H$23),(H12-MIN($H$6:$H$23))/(MAX($H$6:$H$23)-MIN($H$6:$H$23)),0) -> 0.19293058 | K12: =IF(MAX($I$6:$I$23)>MIN($I$6:$I$23),1-(I12-MIN($I$6:$I$23))/(MAX($I$6:$I$23)-MIN($I$6:$I$23)),1) -> 0.85795455 | L12: =100*($D$3*J12+$F$3*K12+$H$3*F12/5) -> 63.455859
A13: 8 | B13: Saini, Doctor And Char | C13: S009 | D13: Germany | E13: 4 | F13: 4 | G13: 2 | H13: 657783.34 | I13: 0 | J13: =IF(MAX($H$6:$H$23)>MIN($H$6:$H$23),(H13-MIN($H$6:$H$23))/(MAX($H$6:$H$23)-MIN($H$6:$H$23)),0) -> 0.21402722 | K13: =IF(MAX($I$6:$I$23)>MIN($I$6:$I$23),1-(I13-MIN($I$6:$I$23))/(MAX($I$6:$I$23)-MIN($I$6:$I$23)),1) -> 1 | L13: =100*($D$3*J13+$F$3*K13+$H$3*F13/5) -> 62.561089
A14: 9 | B14: Bahl, Mander And Chada | C14: S003 | D14: Vietnam | E14: 2.9 | F14: 2.9 | G14: 4 | H14: 870624.82 | I14: 0 | J14: =IF(MAX($H$6:$H$23)>MIN($H$6:$H$23),(H14-MIN($H$6:$H$23))/(MAX($H$6:$H$23)-MIN($H$6:$H$23)),0) -> 0.32089358 | K14: =IF(MAX($I$6:$I$23)>MIN($I$6:$I$23),1-(I14-MIN($I$6:$I$23))/(MAX($I$6:$I$23)-MIN($I$6:$I$23)),1) -> 1 | L14: =100*($D$3*J14+$F$3*K14+$H$3*F14/5) -> 60.235743
A15: 10 | B15: Raj-Palla | C15: S014 | D15: Unknown | E15: 2.5 | F15: 2.5 | G15: 5 | H15: 1166889.1 | I15: 0.019354839 | J15: =IF(MAX($H$6:$H$23)>MIN($H$6:$H$23),(H15-MIN($H$6:$H$23))/(MAX($H$6:$H$23)-MIN($H$6:$H$23)),0) -> 0.46964597 | K15: =IF(MAX($I$6:$I$23)>MIN($I$6:$I$23),1-(I15-MIN($I$6:$I$23))/(MAX($I$6:$I$23)-MIN($I$6:$I$23)),1) -> 0.87903226 | L15: =100*($D$3*J15+$F$3*K15+$H$3*F15/5) -> 60.156806
A16: 11 | B16: Babu And Sons | C16: S008 | D16: India | E16: 3.7 | F16: 3.7 | G16: 2 | H16: 611245.71 | I16: 0 | J16: =IF(MAX($H$6:$H$23)>MIN($H$6:$H$23),(H16-MIN($H$6:$H$23))/(MAX($H$6:$H$23)-MIN($H$6:$H$23)),0) -> 0.19066097 | K16: =IF(MAX($I$6:$I$23)>MIN($I$6:$I$23),1-(I16-MIN($I$6:$I$23))/(MAX($I$6:$I$23)-MIN($I$6:$I$23)),1) -> 1 | L16: =100*($D$3*J16+$F$3*K16+$H$3*F16/5) -> 59.826439
A17: 12 | B17: Zacharia, Agarwal And Sankar | C17: S012 | D17: Vietnam | E17: 3 | F17: 3 | G17: 5 | H17: 1387406.7 | I17: 0.080520613 | J17: =IF(MAX($H$6:$H$23)>MIN($H$6:$H$23),(H17-MIN($H$6:$H$23))/(MAX($H$6:$H$23)-MIN($H$6:$H$23)),0) -> 0.58036649 | K17: =IF(MAX($I$6:$I$23)>MIN($I$6:$I$23),1-(I17-MIN($I$6:$I$23))/(MAX($I$6:$I$23)-MIN($I$6:$I$23)),1) -> 0.49674617 | L17: =100*($D$3*J17+$F$3*K17+$H$3*F17/5) -> 56.117045
... A23: 18 | B23: Rege, Kurian And Gulati | C23: S017 | D23: Vietnam | E23: 2.7 | F23: 2.7 | G23: 1 | H23: 231513.82 | I23: 0.16 | J23: =IF(MAX($H$6:$H$23)>MIN($H$6:$H$23),(H23-MIN($H$6:$H$23))/(MAX($H$6:$H$23)-MIN($H$6:$H$23)),0) -> 0 | K23: =IF(MAX($I$6:$I$23)>MIN($I$6:$I$23),1-(I23-MIN($I$6:$I$23))/(MAX($I$6:$I$23)-MIN($I$6:$I$23)),1) -> 0 | L23: =100*($D$3*J23+$F$3*K23+$H$3*F23/5) -> 16.2

Sheet KPI7_Repeat_Rate
A1: KPI 7 · Customer repeat-purchase rate (90 days)
A2: Share of customers with ≥1 additional distinct completed order within 90 days of their first completed order. Customers with unknown key excluded. "Eligible" excludes customers whose 90-day window had not yet closed at the data end date.
A4: Customers with ≥1 completed order | B4: 98
A5: Repeat buyers (≤90 days) | B5: 9
A6: Repeat-purchase rate (all customers) | B6: =B5/B4 -> 0.091836735
A8: Customers with a closed 90-day window | B8: 93
A9: Repeat buyers among those | B9: 8
A10: Repeat-purchase rate (eligible only) | B10: =B9/B8 -> 0.086021505
A12: Data end date: 2025-12-01

Sheet KPI8_Payment_Recon
A1: KPI 8 · Payment reconciliation & anomaly report
A2: Order total = Σ line net_amount (all statuses). Paid = Σ payments with status Success. Variance beyond ±1 flags Under/Over-payment. Flags can combine. Orders in payments but absent from FACT_ORDERS are "Orphan".
A4: Order | B4: Status | C4: Order total | D4: Payment rows | E4: Success rows | F4: Paid (Success) | G4: Payment statuses | H4: Flag | I4: Variance | K4: Flag | L4: Orders
A5: O00001 | B5: Completed | C5: 109114.18 | D5: 1 | E5: 1 | F5: 109114.18 | G5: Success | H5: OK | I5: =IF(ISNUMBER(C5),F5-C5,"n/a") -> 0 | K5: OK | L5: =COUNTIF($H$5:$H$332,"*"&K5&"*") -> 110
A6: O00002 | B6: Cancelled | C6: 21724.64 | D6: 1 | E6: 0 | F6: 0 | G6: Refunded | H6: No successful payment | I6: =IF(ISNUMBER(C6),F6-C6,"n/a") -> -21724.64 | K6: No successful payment | L6: =COUNTIF($H$5:$H$332,"*"&K6&"*") -> 88
A7: O00003 | B7: Completed | C7: 33974.88 | D7: 1 | E7: 0 | F7: 0 | G7: Pending | H7: No successful payment | I7: =IF(ISNUMBER(C7),F7-C7,"n/a") -> -33974.88 | K7: Underpaid | L7: =COUNTIF($H$5:$H$332,"*"&K7&"*") -> 46
A8: O00004 | B8: Completed | C8: 180629.84 | D8: 1 | E8: 1 | F8: 180629.84 | G8: Success | H8: OK | I8: =IF(ISNUMBER(C8),F8-C8,"n/a") -> 0 | K8: Overpaid | L8: =COUNTIF($H$5:$H$332,"*"&K8&"*") -> 40
A9: O00005 | B9: Completed | C9: 104397.68 | D9: 1 | E9: 1 | F9: 73078.38 | G9: Success | H9: Underpaid | I9: =IF(ISNUMBER(C9),F9-C9,"n/a") -> -31319.3 | K9: Paid but order Cancelled | L9: =COUNTIF($H$5:$H$332,"*"&K9&"*") -> 35
A10: O00006 | B10: Completed | C10: 17880.99 | D10: 1 | E10: 1 | F10: 17880.99 | G10: Success | H10: OK | I10: =IF(ISNUMBER(C10),F10-C10,"n/a") -> 0 | K10: Orphan payment (order not in FACT_ORDERS) | L10: =COUNTIF($H$5:$H$332,"*"&K10&"*") -> 10
A11: O00007 | B11: Completed | C11: 57672.52 | D11: 1 | E11: 1 | F11: 57672.52 | G11: Success | H11: OK | I11: =IF(ISNUMBER(C11),F11-C11,"n/a") -> 0 | K11: No payment row | L11: =COUNTIF($H$5:$H$332,"*"&K11&"*") -> 8
A12: O00008 | B12: Completed | C12: 141201.64 | D12: 1 | E12: 1 | F12: 168821.36 | G12: Success | H12: Overpaid | I12: =IF(ISNUMBER(C12),F12-C12,"n/a") -> 27619.72 | K12: Conflicting payment statuses | L12: =COUNTIF($H$5:$H$332,"*"&K12&"*") -> 5
A13: O00009 | B13: Completed | C13: 40778.86 | D13: 1 | E13: 0 | F13: 0 | G13: Refunded | H13: No successful payment | I13: =IF(ISNUMBER(C13),F13-C13,"n/a") -> -40778.86
A14: O00010 | B14: Completed | C14: 168178.45 | D14: 1 | E14: 1 | F14: 168178.45 | G14: Success | H14: OK | I14: =IF(ISNUMBER(C14),F14-C14,"n/a") -> 0
A15: O00011 | B15: Completed | C15: 43233.87 | D15: 1 | E15: 1 | F15: 43233.87 | G15: Success | H15: OK | I15: =IF(ISNUMBER(C15),F15-C15,"n/a") -> 0
A16: O00012 | B16: Completed | C16: 141177.62 | D16: 1 | E16: 0 | F16: 0 | G16: Failed | H16: No successful payment | I16: =IF(ISNUMBER(C16),F16-C16,"n/a") -> -141177.62
A17: O00013 | B17: Completed | C17: 25431.4 | D17: 1 | E17: 0 | F17: 0 | G17: Failed | H17: No successful payment | I17: =IF(ISNUMBER(C17),F17-C17,"n/a") -> -25431.4
A18: O00014 | B18: Returned | C18: 139604.32 | D18: 1 | E18: 1 | F18: 156502.06 | G18: Success | H18: Overpaid | I18: =IF(ISNUMBER(C18),F18-C18,"n/a") -> 16897.74
A19: O00015 | B19: Completed | C19: 130237.17 | D19: 1 | E19: 1 | F19: 130237.17 | G19: Success | H19: OK | I19: =IF(ISNUMBER(C19),F19-C19,"n/a") -> 0
A20: O00016 | B20: Cancelled | C20: 80420.7 | D20: 1 | E20: 0 | F20: 0 | G20: Refunded | H20: No successful payment | I20: =IF(ISNUMBER(C20),F20-C20,"n/a") -> -80420.7
A21: O00017 | B21: Completed | C21: 27430.41 | D21: 0 | E21: 0 | F21: 0 | H21: No payment row | I21: =IF(ISNUMBER(C21),F21-C21,"n/a") -> -27430.41
A22: O00018 | B22: Returned | C22: 188218.14 | D22: 1 | E22: 1 | F22: 131752.7 | G22: Success | H22: Underpaid | I22: =IF(ISNUMBER(C22),F22-C22,"n/a") -> -56465.44
A23: O00019 | B23: Pending | C23: 140291.34 | D23: 0 | E23: 0 | F23: 0 | H23: No payment row | I23: =IF(ISNUMBER(C23),F23-C23,"n/a") -> -140291.34
A24: O00020 | B24: Completed | C24: 161580.74 | D24: 1 | E24: 1 | F24: 210054.96 | G24: Success | H24: Overpaid | I24: =IF(ISNUMBER(C24),F24-C24,"n/a") -> 48474.22
A25: O00021 | B25: Pending | C25: 29190.88 | D25: 1 | E25: 0 | F25: 0 | G25: Refunded | H25: No successful payment | I25: =IF(ISNUMBER(C25),F25-C25,"n/a") -> -29190.88
A26: O00022 | B26: Cancelled | C26: 11854.78 | D26: 1 | E26: 1 | F26: 5927.39 | G26: Success | H26: Underpaid; Paid but order Cancelled | I26: =IF(ISNUMBER(C26),F26-C26,"n/a") -> -5927.39
A27: O00023 | B27: Completed | C27: 22602.06 | D27: 1 | E27: 0 | F27: 0 | G27: Failed | H27: No successful payment | I27: =IF(ISNUMBER(C27),F27-C27,"n/a") -> -22602.06
A28: O00024 | B28: Completed | C28: 98196.55 | D28: 1 | E28: 1 | F28: 98196.55 | G28: Success | H28: OK | I28: =IF(ISNUMBER(C28),F28-C28,"n/a") -> 0
A29: O00025 | B29: Completed | C29: 64052.43 | D29: 1 | E29: 1 | F29: 64052.43 | G29: Success | H29: OK | I29: =IF(ISNUMBER(C29),F29-C29,"n/a") -> 0
A30: O00026 | B30: Returned | C30: 74805.15 | D30: 1 | E30: 1 | F30: 74805.15 | G30: Success | H30: OK | I30: =IF(ISNUMBER(C30),F30-C30,"n/a") -> 0
A31: O00027 | B31: Cancelled | C31: 58166.47 | D31: 1 | E31: 1 | F31: 58166.47 | G31: Success | H31: Paid but order Cancelled | I31: =IF(ISNUMBER(C31),F31-C31,"n/a") -> 0
A32: O00028 | B32: Completed | C32: 134660.86 | D32: 1 | E32: 1 | F32: 67330.43 | G32: Success | H32: Underpaid | I32: =IF(ISNUMBER(C32),F32-C32,"n/a") -> -67330.43
A33: O00029 | B33: Cancelled | C33: 87102.46 | D33: 1 | E33: 1 | F33: 113233.2 | G33: Success | H33: Overpaid; Paid but order Cancelled | I33: =IF(ISNUMBER(C33),F33-C33,"n/a") -> 26130.74
A34: O00030 | B34: Pending | C34: 135193.83 | D34: 1 | E34: 1 | F34: 143687.55 | G34: Success | H34: Overpaid | I34: =IF(ISNUMBER(C34),F34-C34,"n/a") -> 8493.72
A35: O00031 | B35: Returned | C35: 102935.09 | D35: 1 | E35: 1 | F35: 102734.51 | G35: Success | H35: Underpaid | I35: =IF(ISNUMBER(C35),F35-C35,"n/a") -> -200.58
... A43: O00039 | B43: Completed | C43: 32157.81 | D43: 1 | E43: 1 | F43: 54738.31 | G43: Success | H43: Overpaid | I43: =IF(ISNUMBER(C43),F43-C43,"n/a") -> 22580.5
A44: O00040 | B44: Completed | C44: 107969.1 | D44: 0 | E44: 0 | F44: 0 | H44: No payment row | I44: =IF(ISNUMBER(C44),F44-C44,"n/a") -> -107969.1
A45: O00041 | B45: Completed | C45: 88663.82 | D45: 1 | E45: 0 | F45: 0 | G45: Failed | H45: No successful payment | I45: =IF(ISNUMBER(C45),F45-C45,"n/a") -> -88663.82
A46: O00042 | B46: Completed | C46: 31749.05 | D46: 1 | E46: 1 | F46: 27686.04 | G46: Success | H46: Underpaid | I46: =IF(ISNUMBER(C46),F46-C46,"n/a") -> -4063.01
A47: O00043 | B47: Cancelled | C47: 100493.15 | D47: 2 | E47: 1 | F47: 320939.45 | G47: Pending/Success | H47: Overpaid; Conflicting payment statuses; Paid but order Cancelled | I47: =IF(ISNUMBER(C47),F47-C47,"n/a") -> 220446.3
A48: O00044 | B48: Completed | C48: 70379.66 | D48: 1 | E48: 1 | F48: 70379.66 | G48: Success | H48: OK | I48: =IF(ISNUMBER(C48),F48-C48,"n/a") -> 0
...

Sheet KPI9_Margin_Risk
A1: Stretch · Margin risk report (products sold at a loss)
A2: Line is "at a loss" when unit_price × (1 − discount%) < product cost_price. Revenue exposed = net_amount of those lines; est. loss = (cost − effective price) × qty. Unknown product and zero-price lines excluded.
A4: Lines at a loss | C4: 163 | D4: of 758
A5: Quantity exposed | C5: 505
A6: Revenue exposed | C6: 4088203.4 | D6: =C6/28565694.61 -> 0.14311584 | E6: of margin-eligible revenue
A7: Estimated loss | C7: 1795100.8
A9: product_id | B9: product_name | C9: category | D9: lines | E9: qty_exposed | F9: revenue_exposed | G9: est_loss | H9: avg_cost | I9: avg_eff_price
A10: P065 | B10: Footwear Item 65 | C10: Fashion | D10: 19 | E10: 66 | F10: 936864.71 | G10: 600320.85 | H10: 23290.69 | I10: 14218.09
A11: P013 | B11: Appliances Item 13 | C11: Home & Kitchen | D11: 12 | E11: 27 | F11: 375725.46 | G11: 297667.78 | H11: 24940.49 | I11: 14060.412
A12: P039 | B12: Fitness Item 39 (Revised) | C12: Sports | D12: 7 | E12: 24 | F12: 125100.76 | G12: 224757.08 | H12: 14577.41 | I12: 5236.776
A13: P060 | B13: Staples Item 60 (Revised) | C13: Grocery | D13: 9 | E13: 28 | F13: 301387.3 | G13: 218747.7 | H13: 18576.25 | I13: 10862.541
A14: P001 | B14: Accessories Item 1 (Revised) | C14: Electronics | D14: 6 | E14: 14 | F14: 144986.74 | G14: 90207.796 | H14: 16799.61 | I14: 10305.43
A15: P020 | B15: Beverages Item 20 | C15: Grocery | D15: 15 | E15: 48 | F15: 158467.26 | G15: 89778.188 | H15: 5171.78 | I15: 3307.4587
A16: P028 | B16: Appliances Item 28 | C16: Home & Kitchen | D16: 8 | E16: 20 | F16: 132460.02 | G16: 56691.575 | H16: 9457.58 | I16: 6767.3719
A17: P006 | B17: Furniture Item 6 | C17: Home & Kitchen | D17: 10 | E17: 27 | F17: 71720.4 | G17: 51127.705 | H17: 4549.93 | I17: 2691.3046
A18: P051 | B18: Footwear Item 51 | C18: Fashion | D18: 5 | E18: 12 | F18: 22435.61 | G18: 32462.588 | H18: 4574.85 | I18: 2301.2365
A19: P002 | B19: Furniture Item 2 | C19: Home & Kitchen | D19: 6 | E19: 26 | F19: 212011.47 | G19: 22694.953 | H19: 9027.17 | I19: 8128.7652
A20: P027 | B20: Appliances Item 27 | C20: Home & Kitchen | D20: 4 | E20: 16 | F20: 271265.15 | G20: 20305.572 | H20: 18223.17 | I20: 16954.072
A21: P010 | B21: Accessories Item 10 | C21: Electronics | D21: 10 | E21: 31 | F21: 33517.62 | G21: 20132.847 | H21: 1730.66 | I21: 1072.5636
... A38: P005 | B38: Staples Item 5 | C38: Grocery | D38: 1 | E38: 2 | F38: 28697.52 | G38: 100.54 | H38: 14399.03 | I38: 14348.76

Sheet Data_Profiling
A1: Data profiling & cleansing report
A2: Issues found, rule applied, and before/after counts. "Before/After" = records (or columns) affected before the rule vs remaining after.
A4: Table | B4: Issue found | C4: Rule applied | D4: Before | E4: After
A5: FACT_ORDERS | B5: 16,365 empty spill-over columns (Column1..ColumnN) in the sheet | C5: Dropped all unnamed empty columns | D5: 16384 | E5: 19
A6: FACT_ORDERS | B6: Channel labels (Web/App/Store) checked for case/space variants | C6: Trim + title-case; 3 distinct values remain | D6: 3 | E6: 3
A7: FACT_ORDERS | B7: Order lines with unknown customer (key -1) | C7: Kept for revenue KPIs; excluded from customer-level KPIs (2,3,7); reported separately | D7: 767 | E7: 730
A8: FACT_ORDERS | B8: Order lines with unknown product (key -1) | C8: Kept; category = "Unknown"; excluded from product/supplier KPIs (5,6,9) | D8: 767 | E8: 759
A9: FACT_ORDERS | B9: Order lines with unit_price = 0 | C9: Revenue kept as recorded (0); excluded from margin KPI | D9: 767 | E9: 766
A10: FACT_ORDERS | B10: gross - discount = net integrity check | C10: All rows pass | D10: 767 | E10: 767
A11: FACT_RETURNS | B11: Returns with return date earlier than order date (return_before_order) | C11: Flagged; kept because refunds are attributed to the ORDER month, not the return month | D11: 59 | E11: 59
A12: FACT_RETURNS | B12: Returns with status Rejected / Pending | C12: Excluded: only Approved returns reduce revenue or count as returned quantity | D12: 59 | E12: 28
A13: FACT_RETURNS | B13: Approved returns with NULL refund_amount | C13: Imputed as full line net_amount | D13: 1 | E13: 0
A14: FACT_RETURNS | B14: Refunds larger than the line net_amount | C14: Capped at line net_amount | D14: 4 | E14: 0
A15: DIM_PRODUCTS | B15: Duplicate product_id / conflicting records; "(Revised)" name suffix on 4 products | C15: product_id is unique (0 duplicates); suffix kept as-is, no merge needed | D15: 71 | E15: 71
A16: DIM_PRODUCTS | B16: Category labels | C16: Trim/title-case; 5 real categories + Unknown | D16: 6 | E16: 6
... A23: FACT_PAYMENTS | B23: 10 payment rows (8 orders) reference orders absent from FACT_ORDERS (is_orphan_order = TRUE; customer −1) | C23: Kept and reported as "Orphan payment" in KPI 8 | D23: 10 | E23: 10
A24: FACT_PAYMENTS | B24: 8 orders have no payment row; 88 orders have no Success payment; 5 orders have mixed statuses | C24: Flagged in KPI 8, not corrected
A25: FACT_RETURNS | B25: 29 of 59 returns carry return_before_order = TRUE (return date precedes order date) | C25: Flagged only; refunds attributed to order month so the date conflict does not affect KPIs | D25: 29 | E25: 29
A26: DIM_PRODUCTS | B26: 11 products have cost_price above list unit_price; 3 products have NULL/0 list price | C26: Handled at line level in KPI 9 (effective price vs cost)
A28: Row counts (curated)
A29: Table | B29: Rows
A30: DIM_CUSTOMERS | B30: 159
A31: DIM_SUPPLIERS | B31: 19
A32: DIM_PRODUCTS | B32: 71
A33: DIM_DATE | B33: 2271
A34: FACT_ORDERS | B34: 767
A35: FACT_PAYMENTS | B35: 325
A36: FACT_RETURNS | B36: 59

Sheet Data_Model
A1: Data model (star schema) & SCD approach
A4: Table | B4: Design | C4: Notes
A5: FACT_ORDERS | B5: Grain: order line. FKs → DIM_CUSTOMERS, DIM_PRODUCTS, DIM_DATE (order_date_key). Measures: quantity, unit_price, discount_pct, gross/discount/net amount. Degenerate dims: order_id, channel, order_status. | C5: Unknown member key −1 for orphaned customer/product references
A6: FACT_RETURNS | B6: Grain: return event on an order line. FK → FACT_ORDERS (fact_order_key), DIM_DATE. Measure: refund_amount. | C6: Only Approved rows reduce revenue
A7: FACT_PAYMENTS | B7: Grain: payment attempt. Joins to orders on order_id (degenerate). FK → DIM_CUSTOMERS, DIM_DATE. | C7: is_orphan_order marks payments without a matching order
A8: DIM_CUSTOMERS | B8: SCD Type 2: surrogate customer_key, natural key customer_id, effective_from/effective_to, is_current. Segment/city changes insert a new row and close the old one (effective_to = new effective_from − 1 day). | C8: Currently 1 row per customer (no history yet). Facts store the surrogate key valid at order time; KPIs on current attributes join through customer_id + is_current.
A9: DIM_PRODUCTS | B9: Type 1 (overwrite). FK supplier_key → DIM_SUPPLIERS. Category standardized.
A10: DIM_SUPPLIERS | B10: Type 1. rating_raw kept for audit, rating_normalized on a 0–5 scale.
A11: DIM_DATE | B11: Calendar dimension keyed yyyymmdd; −1 for unknown.
A14: Full DDL: schema.sql (delivered alongside this workbook).

Sheet Assumptions_README
A1: Assumptions, edge-case decisions & trade-offs
A4: # | B4: Assumption / decision
A5: A1 | B5: Realised sales = order_status Completed or Returned. Cancelled and Pending lines are excluded from revenue KPIs (1, 4, 5, 6, 9 uses all lines). KPI 2, 3, 7 use Completed only, as specified.
A6: A2 | B6: Refunds: only Approved returns reduce revenue. Return quantity = full line quantity (no partial-quantity field). NULL refund on an approved return → full line net; refunds above line net are capped.
A7: A3 | B7: Refunds are attributed to the ORDER month (not return month) because 29 of 59 returns have return dates before the order date.
A8: A4 | B8: Unknown customer (key −1, 37 lines): kept in revenue KPIs, excluded from customer KPIs (2, 3, 7); value reported as memo in KPI 2.
A9: A5 | B9: Unknown product (key −1, 8 lines): category "Unknown" in KPI 1; excluded from product and supplier KPIs. No duplicate product_ids exist, so no merge was needed; "(Revised)" names kept as-is.
A10: A6 | B10: KPI 5 threshold: ≥30 ordered units (19 of 69 products qualify; a lower bar lets 1–2 unit products reach 50%+). Tie-break by higher volume. Many products have 0% return, so the bottom 10 is a tie on 0% broken by volume.
A11: A7 | B11: KPI 6 weights 40/30/30 are editable in the sheet. Revenue and return rate min-max scaled across suppliers. Unknown supplier excluded.
A12: A8 | B12: KPI 7: "within 90 days" = ≤90 days from first completed order date, different order_id. Both all-customer and eligible-only (window closed before 2025-12-01) rates shown.
A13: A9 | B13: KPI 8: tolerance ±1 currency unit. Only Success rows count as paid; Refunded/Failed/Pending do not. Cancelled orders with a Success payment are flagged.
A14: A10 | B14: KPI 4: MoM computed on Jan-2024 → Dec-2025 with zero-filled gaps; Nov/Dec-2025 contain very few orders so late growth rates are noisy.
A15: A11 | B15: Source workbook is already a curated star schema (not raw CSVs); "raw → curated" therefore covers structural cleanup (16,365 empty columns), integrity checks and business-rule derivation, not re-keying.
A16: A12 | B16: Trade-off: KPI 1 and dashboard tiles are live formulas; KPIs needing window logic, ranking or multi-table joins are pipeline.py outputs to keep the workbook auditable and fast.

Sheet AI_Usage_Log
A1: AI usage log
A4: Tool | B4: Sample prompt | C4: How output was validated
A5: Claude (Sonnet 5.5) | B5: "Create the dashboard in this Excel and build the 8 KPIs (+ stretch) with data-quality handling." | C5: Profiled every sheet first; reconciled KPI 1 formula total to pipeline total (difference = 0); checked gross−discount=net on all 767 lines; spot-checked order O00001 payment vs order total.
A6: Claude (Sonnet 5.5) | B6: "Resolve return refunds exceeding line net / NULL refunds before computing net revenue." | C6: Counted affected rows (4 capped, 1 imputed) and confirmed no refund > net after the rule.
A7: Claude (Sonnet 5.5) | B7: "Compute supplier composite score with normalized ratings." | C7: Verified rating_normalized = raw/2 when raw>5 for all 3 affected suppliers; score recalculates from editable weights.

Sheet Curated_Items
A1: Curated order-line fact (raw → curated)
A2: One row per order line. Net revenue and the "recognized" flag are live formulas; refunds = Approved returns only (capped at line net). Recognized = Completed + Returned orders (assumption A1).
A4: order_item_id | B4: order_id | C4: order_date | D4: order_month | E4: customer_id | F4: customer_segment | G4: product_id | H4: category | I4: channel | J4: order_status | K4: quantity | L4: unit_price | M4: discount_pct | N4: gross_amount | O4: discount_amount | P4: net_amount | Q4: refund_amt | R4: returned_qty | S4: net_revenue | T4: recognized
A5: OI000001 | B5: O00079 | C5: 45320 | D5: 2024-01 | E5: C0101 | F5: Bronze | G5: P009 | H5: Home & Kitchen | I5: App | J5: Completed | K5: 3 | L5: 26274.11 | M5: 5 | N5: 78822.33 | O5: 3941.12 | P5: 74881.21 | Q5: 0 | R5: 0 | S5: =P5-Q5 -> 74881.21 | T5: =IF(OR(J5="Completed",J5="Returned"),1,0) -> 1
A6: OI000002 | B6: O00079 | C6: 45320 | D6: 2024-01 | E6: C0101 | F6: Bronze | G6: P065 | H6: Fashion | I6: App | J6: Completed | K6: 4 | L6: 15706.03 | M6: 20 | N6: 62824.12 | O6: 12564.82 | P6: 50259.3 | Q6: 41619.4 | R6: 4 | S6: =P6-Q6 -> 8639.9 | T6: =IF(OR(J6="Completed",J6="Returned"),1,0) -> 1
A7: OI000003 | B7: O00079 | C7: 45320 | D7: 2024-01 | E7: C0101 | F7: Bronze | G7: P015 | H7: Sports | I7: App | J7: Completed | K7: 1 | L7: 4516.1 | M7: 5 | N7: 4516.1 | O7: 225.8 | P7: 4290.3 | Q7: 0 | R7: 0 | S7: =P7-Q7 -> 4290.3 | T7: =IF(OR(J7="Completed",J7="Returned"),1,0) -> 1
A8: OI000004 | B8: O00079 | C8: 45320 | D8: 2024-01 | E8: C0101 | F8: Bronze | G8: P023 | H8: Fashion | I8: App | J8: Completed | K8: 5 | L8: 3019.36 | M8: 10 | N8: 15096.8 | O8: 1509.68 | P8: 13587.12 | Q8: 0 | R8: 0 | S8: =P8-Q8 -> 13587.12 | T8: =IF(OR(J8="Completed",J8="Returned"),1,0) -> 1
A9: OI000005 | B9: O00318 | C9: 45807 | D9: 2025-05 | E9: C0142 | F9: Platinum | G9: P070 | H9: Fashion | I9: Store | J9: Completed | K9: 4 | L9: 3962.52 | M9: 10 | N9: 15850.08 | O9: 1585.01 | P9: 14265.07 | Q9: 0 | R9: 0 | S9: =P9-Q9 -> 14265.07 | T9: =IF(OR(J9="Completed",J9="Returned"),1,0) -> 1
A10: OI000006 | B10: O00318 | C10: 45807 | D10: 2025-05 | E10: C0142 | F10: Platinum | G10: P049 | H10: Grocery | I10: Store | J10: Completed | K10: 5 | L10: 12393.99 | M10: 10 | N10: 61969.95 | O10: 6197 | P10: 55772.95 | Q10: 0 | R10: 0 | S10: =P10-Q10 -> 55772.95 | T10: =IF(OR(J10="Completed",J10="Returned"),1,0) -> 1
A11: OI000007 | B11: O00130 | C11: 45477 | D11: 2024-07 | E11: C0139 | F11: Silver | G11: P027 | H11: Home & Kitchen | I11: Store | J11: Pending | K11: 2 | L11: 20550.39 | M11: 0 | N11: 41100.78 | O11: 0 | P11: 41100.78 | Q11: 0 | R11: 0 | S11: =P11-Q11 -> 41100.78 | T11: =IF(OR(J11="Completed",J11="Returned"),1,0) -> 0
A12: OI000008 | B12: O00130 | C12: 45477 | D12: 2024-07 | E12: C0139 | F12: Silver | G12: P018 | H12: Sports | I12: Store | J12: Pending | K12: 5 | L12: 17477.91 | M12: 10 | N12: 87389.55 | O12: 8738.96 | P12: 78650.59 | Q12: 0 | R12: 0 | S12: =P12-Q12 -> 78650.59 | T12: =IF(OR(J12="Completed",J12="Returned"),1,0) -> 0
A13: OI000009 | B13: O00130 | C13: 45477 | D13: 2024-07 | E13: C0139 | F13: Silver | G13: P062 | H13: Home & Kitchen | I13: Store | J13: Pending | K13: 4 | L13: 8493.72 | M13: 5 | N13: 33974.88 | O13: 1698.74 | P13: 32276.14 | Q13: 0 | R13: 0 | S13: =P13-Q13 -> 32276.14 | T13: =IF(OR(J13="Completed",J13="Returned"),1,0) -> 0
A14: OI000010 | B14: O00130 | C14: 45477 | D14: 2024-07 | E14: C0139 | F14: Silver | G14: P063 | H14: Grocery | I14: Store | J14: Pending | K14: 2 | L14: 9269.43 | M14: 5 | N14: 18538.86 | O14: 926.94 | P14: 17611.92 | Q14: 0 | R14: 0 | S14: =P14-Q14 -> 17611.92 | T14: =IF(OR(J14="Completed",J14="Returned"),1,0) -> 0
A15: OI000011 | B15: O00137 | C15: 45860 | D15: 2025-07 | E15: C0060 | F15: Platinum | G15: P049 | H15: Grocery | I15: App | J15: Completed | K15: 5 | L15: 12393.99 | M15: 10 | N15: 61969.95 | O15: 6197 | P15: 55772.95 | Q15: 0 | R15: 0 | S15: =P15-Q15 -> 55772.95 | T15: =IF(OR(J15="Completed",J15="Returned"),1,0) -> 1
A16: OI000012 | B16: O00137 | C16: 45860 | D16: 2025-07 | E16: C0060 | F16: Platinum | G16: P057 | H16: Sports | I16: App | J16: Completed | K16: 1 | L16: 11518.86 | M16: 0 | N16: 11518.86 | O16: 0 | P16: 11518.86 | Q16: 0 | R16: 0 | S16: =P16-Q16 -> 11518.86 | T16: =IF(OR(J16="Completed",J16="Returned"),1,0) -> 1
... A771: OI000796 | B771: O00055 | C771: 45915 | D771: 2025-09 | E771: C0177 | F771: Silver | G771: P069 | H771: Electronics | I771: App | J771: Returned | K771: 2 | L771: 25742.49 | M771: 20 | N771: 51484.98 | O771: 10297 | P771: 41187.98 | Q771: 0 | R771: 0 | S771: =P771-Q771 -> 41187.98 | T771: =IF(OR(J771="Completed",J771="Returned"),1,0) -> 1

Sheet DIM_CUSTOMERS
A1: customer_key | B1: customer_id | C1: full_name | D1: customer_segment | E1: is_active | F1: effective_from | G1: effective_to | H1: is_current | I1: email | J1: phone | K1: city | L1: state | M1: country | N1: signup_date
A2: -1 | B2: UNKNOWN | C2: Unknown customer | D2: Unknown | E2: NO | F2: 1 | G2: 2958465 | H2: =TRUE() -> TRUE
A3: 1 | B3: C0001 | C3: Isaac Bakshi | D3: Bronze | E3: YES | F3: 45008 | G3: 2958465 | H3: =TRUE() -> TRUE | I3: isaac.bakshi1@example.com | J3: 8196001338 | K3: Bangalore | L3: Karnataka | M3: India | N3: 45008
A4: 2 | B4: C0002 | C4: Tanveer Nayar | D4: Gold | E4: YES | F4: 44308 | G4: 2958465 | H4: =TRUE() -> TRUE | I4: tanveer.nayar2@example.com | J4: 9407816184 | K4: Lucknow | L4: Uttar Pradesh | M4: India | N4: 44308
A5: 3 | B5: C0003 | C5: Nicholas Prabhakar | D5: Platinum | E5: YES | F5: 44585 | G5: 2958465 | H5: =TRUE() -> TRUE | I5: nicholas.prabhakar3@example.com | J5: 8327648350 | K5: Jaipur | L5: Rajasthan | M5: India | N5: 44585
A6: 4 | B6: C0004 | C6: Liam Koshy | D6: Bronze | E6: YES | F6: 45012 | G6: 2958465 | H6: =TRUE() -> TRUE | I6: liam.koshy4@example.com | J6: 6532871012 | K6: Kolkata | L6: West Bengal | M6: India | N6: 45012
A7: 5 | B7: C0005 | C7: Harini Choudhury | D7: Gold | E7: YES | F7: 44518 | G7: 2958465 | H7: =TRUE() -> TRUE | I7: harini.choudhury5@example.com | J7: 8281489325 | K7: Bengaluru | L7: Karnataka | M7: India | N7: 44518
A8: 6 | B8: C0006 | C8: Farhan Chada | D8: Platinum | E8: YES | F8: 44997 | G8: 2958465 | H8: =TRUE() -> TRUE | I8: farhan.chada6@example.com | J8: 7824896383 | K8: Jaipur | L8: Rajasthan | M8: India | N8: 44997
A9: 7 | B9: C0007 | C9: Thomas Amble | D9: Gold | E9: YES | F9: 44274 | G9: 2958465 | H9: =TRUE() -> TRUE | I9: thomas.amble7@example.com | J9: 5183473829 | K9: Lucknow | L9: Uttar Pradesh | M9: India | N9: 44274
A10: 8 | B10: C0008 | C10: Guneet Bhat | D10: Bronze | E10: YES | F10: 44637 | G10: 2958465 | H10: =TRUE() -> TRUE | I10: Unknown | J10: 3872624731 | K10: Bengaluru | L10: Karnataka | M10: India | N10: 44637
A11: 9 | B11: C0009 | C11: Daniel Gala | D11: Silver | E11: YES | F11: 44611 | G11: 2958465 | H11: =TRUE() -> TRUE | I11: Unknown | J11: 6872343098 | K11: Pune | L11: Maharashtra | M11: India | N11: 44611
A12: 10 | B12: C0010 | C12: Wahab Raval | D12: Silver | E12: YES | F12: 44535 | G12: 2958465 | H12: =TRUE() -> TRUE | I12: wahab.raval10@example.com | J12: 9169985435 | K12: Delhi | L12: Delhi | M12: India | N12: 44535
A13: 11 | B13: C0011 | C13: Tanay Toor | D13: Silver | E13: YES | F13: 44487 | G13: 2958465 | H13: =TRUE() -> TRUE | I13: tanay.toor11@example.com | J13: 4278498084 | K13: Lucknow | L13: Uttar Pradesh | M13: India | N13: 44487
A14: 12 | B14: C0012 | C14: Aishani Tiwari | D14: Silver | E14: YES | F14: 1 | G14: 2958465 | H14: =TRUE() -> TRUE | I14: aishani.tiwari12@example.com | J14: 0052427868 | K14: Pune | L14: Maharashtra | M14: India
A15: 13 | B15: C0013 | C15: Balveer Parmar | D15: Platinum | E15: YES | F15: 44426 | G15: 2958465 | H15: =TRUE() -> TRUE | I15: balveer.parmar13@example.com | J15: 6923226025 | K15: Chennai | L15: Tamil Nadu | M15: India | N15: 44426
A16: 14 | B16: C0014 | C16: Udant Bajwa | D16: Platinum | E16: YES | F16: 44919 | G16: 2958465 | H16: =TRUE() -> TRUE | I16: udant.bajwa14@example.com | J16: 0000000000 | K16: Kolkata | L16: West Bengal | M16: India | N16: 44919
A17: 15 | B17: C0015 | C17: Chaitanya Sarin | D17: Bronze | E17: YES | F17: 44228 | G17: 2958465 | H17: =TRUE() -> TRUE | I17: chaitanya.sarin15@example.com | J17: 5951484656 | K17: Bangalore | L17: Karnataka | M17: India | N17: 44228
A18: 16 | B18: C0016 | C18: Shivansh Sani | D18: Gold | E18: YES | F18: 45204 | G18: 2958465 | H18: =TRUE() -> TRUE | I18: shivansh.sani16@example.com | J18: 3872148951 | K18: Pune | L18: Maharashtra | M18: India | N18: 45204
A19: 17 | B19: C0017 | C19: Robert Rajagopalan | D19: Platinum | E19: YES | F19: 44737 | G19: 2958465 | H19: =TRUE() -> TRUE | I19: robert.rajagopalan17@example.com | J19: 6328708317 | K19: Lucknow | L19: Uttar Pradesh | M19: India | N19: 44737
A20: 18 | B20: C0018 | C20: Aradhana Verma | D20: Gold | E20: YES | F20: 44727 | G20: 2958465 | H20: =TRUE() -> TRUE | I20: aradhana.verma18@example.com | J20: 4345581223 | K20: Mumbai | L20: Maharashtra | M20: India | N20: 44727
A21: 19 | B21: C0019 | C21: Anmol Rai | D21: Silver | E21: YES | F21: 44718 | G21: 2958465 | H21: =TRUE() -> TRUE | I21: Unknown | J21: 8893734670 | K21: Hyderabad | L21: Telangana | M21: India | N21: 44718
A22: 20 | B22: C0020 | C22: Priya Deshmukh | D22: Bronze | E22: YES | F22: 45115 | G22: 2958465 | H22: =TRUE() -> TRUE | I22: priya.deshmukh20@example.com | J22: 5375564641 | K22: Pune | L22: Maharashtra | M22: India | N22: 45115
A23: 21 | B23: C0021 | C23: William Date | D23: Silver | E23: NO | F23: 44626 | G23: 2958465 | H23: =TRUE() -> TRUE | I23: william.date21@example.com | J23: 4529912419 | K23: Delhi | L23: Delhi | M23: India | N23: 44626
A24: 22 | B24: C0022 | C24: Idika Walia | D24: Bronze | E24: YES | F24: 44665 | G24: 2958465 | H24: =TRUE() -> TRUE | I24: idika.walia22@example.com | J24: 0000000000 | K24: Bangalore | L24: Karnataka | M24: India | N24: 44665
A25: 23 | B25: C0023 | C25: Yagnesh Shetty | D25: Platinum | E25: YES | F25: 44820 | G25: 2958465 | H25: =TRUE() -> TRUE | I25: yagnesh.shetty23@example.com | J25: 5273545494 | K25: Jaipur | L25: Rajasthan | M25: India | N25: 44820
A26: 24 | B26: C0024 | C26: Nidhi Kohli | D26: Bronze | E26: YES | F26: 44208 | G26: 2958465 | H26: =TRUE() -> TRUE | I26: nidhi.kohli24@example.com | J26: 5685574443 | K26: Bengaluru | L26: Karnataka | M26: India | N26: 44208
... A160: 158 | B160: C0177 | C160: Tanay Toor | D160: Silver | E160: YES | F160: 44487 | G160: 2958465 | H160: =TRUE() -> TRUE | I160: tanay.toor11@gmail.com | J160: 4278498084 | K160: Lucknow | L160: Uttar Pradesh | M160: India | N160: 44487

Sheet DIM_SUPPLIERS
A1: supplier_key | B1: supplier_id | C1: supplier_name | D1: country | E1: is_preferred | F1: rating_raw | G1: rating_normalized | H1: contract_start_date
A2: -1 | B2: UNKNOWN | C2: Unknown supplier | D2: Unknown | E2: No
A3: 1 | B3: S001 | C3: Baral, Din And Bhalla | D3: Unknown | E3: No | F3: 4.3 | G3: 4.3 | H3: 43416
A4: 2 | B4: S002 | C4: Varughese Group | D4: Germany | E4: No | F4: 2.5 | G4: 2.5 | H4: 43499
A5: 3 | B5: S003 | C5: Bahl, Mander And Chada | D5: Vietnam | E5: No | F5: 2.9 | G5: 2.9 | H5: 44898
A6: 4 | B6: S004 | C6: Amble, Prashad And Jha | D6: Unknown | E6: Yes | F6: 9.4 | G6: 4.7 | H6: 43684
A7: 5 | B7: S005 | C7: Dhar-Gopal | D7: Germany | E7: Yes | F7: 4.5 | G7: 4.5 | H7: 43661
